#VRML_SIM R2025a utf8

EXTERNPROTO "https://raw.githubusercontent.com/cyberbotics/webots/R2025a/projects/objects/backgrounds/protos/TexturedBackground.proto"
EXTERNPROTO "https://raw.githubusercontent.com/cyberbotics/webots/R2025a/projects/objects/backgrounds/protos/TexturedBackgroundLight.proto"
EXTERNPROTO "https://raw.githubusercontent.com/cyberbotics/webots/R2025a/projects/objects/floors/protos/RectangleArena.proto"
EXTERNPROTO "https://raw.githubusercontent.com/cyberbotics/webots/R2025a/projects/robots/gctronic/e-puck/protos/E-puck.proto"

WorldInfo {
}
Viewpoint {
  orientation 0.3885929133659768 0.4409365980825067 -0.8090552911594909 1.2830088285678063
  position -2.082082166293075 3.4037944040828885 3.0991558153200227
}
TexturedBackground {
}
TexturedBackgroundLight {
}
RectangleArena {
  floorSize 10 10
}
DEF LEFT_SQUARE Solid {
  translation -2 0 0.001
  children [
    Shape {
      geometry Plane {
        size 0.1 4
      }
    }
  ]
}
DEF RIGHT_SQUARE Solid {
  translation 2 0 0.001
  children [
    Shape {
      geometry Plane {
        size 0.1 4
      }
    }
  ]
  name "solid(1)"
}
DEF TOP_SQUARE Solid {
  translation 0 2 0.001
  rotation 0 0 1 1.5708
  children [
    Shape {
      geometry Plane {
        size 0.1 4
      }
    }
  ]
  name "solid(2)"
}
DEF BOTTOM_SQUARE Solid {
  translation 0 -2 0.001
  rotation 0 0 1 1.5708
  children [
    Shape {
      geometry Plane {
        size 0.1 4
      }
    }
  ]
  name "solid(3)"
}
Robot {
  rotation -0.05873448547867834 -0.003953122711390939 0.9982658128155966 -3.007019932286464
  children [
    DEF SENSOR_2 DistanceSensor {
      translation 0.046 -0.02 0.02
      children [
        Shape {
          appearance Appearance {
            material Material {
              diffuseColor 0.8 0.9 0.8
            }
          }
          geometry Box {
            size 0.001 0.005 0.005
          }
        }
      ]
      name "sensor_2"
    }
    DEF SENSOR_1 DistanceSensor {
      translation 0.05 0 0.02
      children [
        Shape {
          appearance Appearance {
            material Material {
              diffuseColor 0.8 0.9 0.8
            }
          }
          geometry Box {
            size 0.001 0.005 0.005
          }
        }
      ]
      name "sensor_1"
    }
    DEF SENSOR_3 DistanceSensor {
      translation 0.046 0.02 0.02
      children [
        Shape {
          appearance Appearance {
            material Material {
              diffuseColor 0.8 0.9 0.8
            }
          }
          geometry Box {
            size 0.001 0.005 0.005
          }
        }
      ]
      name "sensor_3"
    }
    DEF CAMERA_BOTTOM Camera {
      translation 3.18432e-07 0 0.0028
      rotation 0 1 0 3.14159
      children [
        DEF CAMERA Shape {
          appearance Appearance {
            material Material {
              diffuseColor 0.1 0.1 0.4
            }
          }
          geometry Cone {
            bottomRadius 0.01
            height 0.01
          }
        }
      ]
      name "camera_bottom"
    }
    DEF CAMERA_FRONT Camera {
      translation 0.05 0 0.03
      rotation 0 1 0 1.5708
      children [
        DEF CAMERA Shape {
          appearance Appearance {
            material Material {
              diffuseColor 0.1 0.1 0.4
            }
          }
          geometry Cone {
            bottomRadius 0.01
            height 0.01
          }
        }
      ]
      name "camera_front"
    }
    DEF BODY Pose {
      translation 0 0 0.0508
      children [
        Shape {
          appearance Appearance {
            material Material {
              diffuseColor 1 0 0.7
            }
          }
          geometry Cylinder {
            height 0.1
            radius 0.05
          }
        }
      ]
    }
    HingeJoint {
      jointParameters HingeJointParameters {
        position 27.40755867141226
        axis 0 1 0
        anchor 3.98867e-05 0.055 0.02
      }
      device [
        RotationalMotor {
          name "RIGHT_MOTOR"
        }
      ]
      endPoint Solid {
        translation 4.376766822033793e-05 0.05499999998984264 0.019995840396196334
        rotation 0.25129243476054836 0.6846878532818058 0.6841452008166599 3.634361032335386
        children [
          DEF WHEEL Shape {
            appearance Appearance {
              material Material {
                diffuseColor 0.3 0.8 0.8
              }
            }
            geometry Cylinder {
              height 0.01
              radius 0.025
            }
          }
        ]
        boundingObject USE WHEEL
        physics DEF WHEEL_PHYSICS Physics {
        }
      }
    }
    HingeJoint {
      jointParameters HingeJointParameters {
        position 73.18520026701832
        axis 0 1 0
        anchor 3.98867e-05 -0.055 0.02
      }
      device [
        RotationalMotor {
          name "LEFT_MOTOR"
        }
      ]
      endPoint Solid {
        translation 3.496784123130154e-05 -0.055000000010165105 0.01999714296422539
        rotation -0.33380506505118573 -0.6665489796285811 -0.666548300052045 2.4972419354851487
        children [
          USE WHEEL
        ]
        name "solid(1)"
        boundingObject USE WHEEL
        physics Physics {
        }
      }
    }
    DEF TEETH_1 Solid {
      translation 0.07 -0.04 0.027
      children [
        DEF TEETH Shape {
          appearance Appearance {
            material Material {
              diffuseColor 0.4 0.3 0.8
            }
          }
          geometry Box {
            size 0.09 0.01 0.03
          }
        }
      ]
      name "solid(2)"
      boundingObject USE TEETH
      physics Physics {
      }
    }
    DEF TEETH_2 Solid {
      translation 0.07 0.04 0.027
      children [
        USE TEETH
      ]
      name "solid(3)"
      boundingObject USE TEETH
      physics Physics {
      }
    }
  ]
  boundingObject USE BODY
  physics Physics {
  }
  controller "Robot_Controller"
}
DEF Field-Generator E-puck {
  hidden linearVelocity_0 0.00012668056913765034 3.193281336734061e-05 4.220356628603153e-08
  hidden angularVelocity_0 -0.0021289378241296404 0.008445702677848372 7.52138996680323e-11
  translation 4.500270792448076 0.030241718862717235 1.3699360486382162
  rotation 0.0005418693470925839 6.7243900703376e-05 0.9999998509279231 -2.894663232078724
  name "Maze-Generator"
  controller "Create_Stadium"
  supervisor TRUE
}
